[2024-10-19T00:04:09.722+0000] {local_task_job_runner.py:123} INFO - ::group::Pre task execution logs
[2024-10-19T00:04:09.795+0000] {taskinstance.py:2612} INFO - Dependencies all met for dep_context=non-requeueable deps ti=<TaskInstance: example_python_operator.external_python manual__2024-10-18T23:59:57.208019+00:00 [queued]>
[2024-10-19T00:04:09.821+0000] {taskinstance.py:2612} INFO - Dependencies all met for dep_context=requeueable deps ti=<TaskInstance: example_python_operator.external_python manual__2024-10-18T23:59:57.208019+00:00 [queued]>
[2024-10-19T00:04:09.831+0000] {taskinstance.py:2865} INFO - Starting attempt 1 of 1
[2024-10-19T00:04:09.884+0000] {taskinstance.py:2888} INFO - Executing <Task(ExternalPythonOperator): external_python> on 2024-10-18 23:59:57.208019+00:00
[2024-10-19T00:04:09.930+0000] {warnings.py:112} WARNING - /home/***/.local/lib/python3.12/site-packages/***/task/task_runner/standard_task_runner.py:70: DeprecationWarning: This process (pid=404) is multi-threaded, use of fork() may lead to deadlocks in the child.
  pid = os.fork()

[2024-10-19T00:04:09.937+0000] {standard_task_runner.py:72} INFO - Started process 413 to run task
[2024-10-19T00:04:09.945+0000] {standard_task_runner.py:104} INFO - Running: ['***', 'tasks', 'run', 'example_python_operator', 'external_python', 'manual__2024-10-18T23:59:57.208019+00:00', '--job-id', '39', '--raw', '--subdir', '/home/***/.local/lib/python3.12/site-packages/***/example_dags/example_python_operator.py', '--cfg-path', '/tmp/tmpjspo98sh']
[2024-10-19T00:04:09.950+0000] {standard_task_runner.py:105} INFO - Job 39: Subtask external_python
[2024-10-19T00:04:10.115+0000] {task_command.py:467} INFO - Running <TaskInstance: example_python_operator.external_python manual__2024-10-18T23:59:57.208019+00:00 [running]> on host bba1a6f01f4d
[2024-10-19T00:04:10.433+0000] {taskinstance.py:3131} INFO - Exporting env vars: AIRFLOW_CTX_DAG_OWNER='***' AIRFLOW_CTX_DAG_ID='example_python_operator' AIRFLOW_CTX_TASK_ID='external_python' AIRFLOW_CTX_EXECUTION_DATE='2024-10-18T23:59:57.208019+00:00' AIRFLOW_CTX_TRY_NUMBER='1' AIRFLOW_CTX_DAG_RUN_ID='manual__2024-10-18T23:59:57.208019+00:00'
[2024-10-19T00:04:10.438+0000] {logging_mixin.py:190} INFO - Task instance is in running state
[2024-10-19T00:04:10.440+0000] {logging_mixin.py:190} INFO -  Previous state of the Task instance: queued
[2024-10-19T00:04:10.442+0000] {logging_mixin.py:190} INFO - Current task name:external_python state:running start_date:2024-10-19 00:04:09.796482+00:00
[2024-10-19T00:04:10.444+0000] {logging_mixin.py:190} INFO - Dag name:example_python_operator and current dag run status:running
[2024-10-19T00:04:10.446+0000] {taskinstance.py:731} INFO - ::endgroup::
[2024-10-19T00:04:14.853+0000] {baseoperator.py:405} WARNING - ExternalPythonOperator.execute cannot be called outside TaskInstance!
[2024-10-19T00:04:26.829+0000] {process_utils.py:186} INFO - Executing cmd: /home/***/.local/bin/python /tmp/venv-callagd7xo32/script.py /tmp/venv-callagd7xo32/script.in /tmp/venv-callagd7xo32/script.out /tmp/venv-callagd7xo32/string_args.txt /tmp/venv-callagd7xo32/termination.log
[2024-10-19T00:04:27.418+0000] {process_utils.py:190} INFO - Output:
[2024-10-19T00:04:32.803+0000] {job.py:229} INFO - Heartbeat recovered after 23.35 seconds
[2024-10-19T00:05:14.519+0000] {job.py:229} INFO - Heartbeat recovered after 41.87 seconds
[2024-10-19T00:05:25.397+0000] {job.py:239} ERROR - Job heartbeat failed with error
Traceback (most recent call last):
  File "/home/airflow/.local/lib/python3.12/site-packages/sqlalchemy/engine/base.py", line 3371, in _wrap_pool_connect
    return fn()
           ^^^^
  File "/home/airflow/.local/lib/python3.12/site-packages/sqlalchemy/pool/base.py", line 327, in connect
    return _ConnectionFairy._checkout(self)
           ^^^^^^^^^^^^^^^^^^^^^^^^^^^^^^^^
  File "/home/airflow/.local/lib/python3.12/site-packages/sqlalchemy/pool/base.py", line 894, in _checkout
    fairy = _ConnectionRecord.checkout(pool)
            ^^^^^^^^^^^^^^^^^^^^^^^^^^^^^^^^
  File "/home/airflow/.local/lib/python3.12/site-packages/sqlalchemy/pool/base.py", line 493, in checkout
    rec = pool._do_get()
          ^^^^^^^^^^^^^^
  File "/home/airflow/.local/lib/python3.12/site-packages/sqlalchemy/pool/impl.py", line 256, in _do_get
    return self._create_connection()
           ^^^^^^^^^^^^^^^^^^^^^^^^^
  File "/home/airflow/.local/lib/python3.12/site-packages/sqlalchemy/pool/base.py", line 273, in _create_connection
    return _ConnectionRecord(self)
           ^^^^^^^^^^^^^^^^^^^^^^^
  File "/home/airflow/.local/lib/python3.12/site-packages/sqlalchemy/pool/base.py", line 388, in __init__
    self.__connect()
  File "/home/airflow/.local/lib/python3.12/site-packages/sqlalchemy/pool/base.py", line 690, in __connect
    with util.safe_reraise():
         ^^^^^^^^^^^^^^^^^^^
  File "/home/airflow/.local/lib/python3.12/site-packages/sqlalchemy/util/langhelpers.py", line 70, in __exit__
    compat.raise_(
  File "/home/airflow/.local/lib/python3.12/site-packages/sqlalchemy/util/compat.py", line 211, in raise_
    raise exception
  File "/home/airflow/.local/lib/python3.12/site-packages/sqlalchemy/pool/base.py", line 686, in __connect
    self.dbapi_connection = connection = pool._invoke_creator(self)
                                         ^^^^^^^^^^^^^^^^^^^^^^^^^^
  File "/home/airflow/.local/lib/python3.12/site-packages/sqlalchemy/engine/create.py", line 574, in connect
    return dialect.connect(*cargs, **cparams)
           ^^^^^^^^^^^^^^^^^^^^^^^^^^^^^^^^^^
  File "/home/airflow/.local/lib/python3.12/site-packages/sqlalchemy/engine/default.py", line 598, in connect
    return self.dbapi.connect(*cargs, **cparams)
           ^^^^^^^^^^^^^^^^^^^^^^^^^^^^^^^^^^^^^
  File "/home/airflow/.local/lib/python3.12/site-packages/psycopg2/__init__.py", line 122, in connect
    conn = _connect(dsn, connection_factory=connection_factory, **kwasync)
           ^^^^^^^^^^^^^^^^^^^^^^^^^^^^^^^^^^^^^^^^^^^^^^^^^^^^^^^^^^^^^^^
psycopg2.OperationalError: could not translate host name "postgres" to address: Temporary failure in name resolution


The above exception was the direct cause of the following exception:

Traceback (most recent call last):
  File "/home/airflow/.local/lib/python3.12/site-packages/airflow/jobs/job.py", line 233, in heartbeat
    heartbeat_callback(session)
  File "/home/airflow/.local/lib/python3.12/site-packages/airflow/utils/session.py", line 94, in wrapper
    return func(*args, **kwargs)
           ^^^^^^^^^^^^^^^^^^^^^
  File "/home/airflow/.local/lib/python3.12/site-packages/airflow/jobs/local_task_job_runner.py", line 284, in heartbeat_callback
    self.task_instance.refresh_from_db()
  File "/home/airflow/.local/lib/python3.12/site-packages/airflow/utils/session.py", line 97, in wrapper
    return func(*args, session=session, **kwargs)
           ^^^^^^^^^^^^^^^^^^^^^^^^^^^^^^^^^^^^^^
  File "/home/airflow/.local/lib/python3.12/site-packages/airflow/models/taskinstance.py", line 2358, in refresh_from_db
    _refresh_from_db(task_instance=self, session=session, lock_for_update=lock_for_update)
  File "/home/airflow/.local/lib/python3.12/site-packages/airflow/models/taskinstance.py", line 872, in _refresh_from_db
    ti = TaskInstance.get_task_instance(
         ^^^^^^^^^^^^^^^^^^^^^^^^^^^^^^^
  File "/home/airflow/.local/lib/python3.12/site-packages/airflow/api_internal/internal_api_call.py", line 139, in wrapper
    return func(*args, **kwargs)
           ^^^^^^^^^^^^^^^^^^^^^
  File "/home/airflow/.local/lib/python3.12/site-packages/airflow/utils/session.py", line 94, in wrapper
    return func(*args, **kwargs)
           ^^^^^^^^^^^^^^^^^^^^^
  File "/home/airflow/.local/lib/python3.12/site-packages/airflow/models/taskinstance.py", line 2344, in get_task_instance
    return query.one_or_none()
           ^^^^^^^^^^^^^^^^^^^
  File "/home/airflow/.local/lib/python3.12/site-packages/sqlalchemy/orm/query.py", line 2850, in one_or_none
    return self._iter().one_or_none()
           ^^^^^^^^^^^^
  File "/home/airflow/.local/lib/python3.12/site-packages/sqlalchemy/orm/query.py", line 2916, in _iter
    result = self.session.execute(
             ^^^^^^^^^^^^^^^^^^^^^
  File "/home/airflow/.local/lib/python3.12/site-packages/sqlalchemy/orm/session.py", line 1716, in execute
    conn = self._connection_for_bind(bind)
           ^^^^^^^^^^^^^^^^^^^^^^^^^^^^^^^
  File "/home/airflow/.local/lib/python3.12/site-packages/sqlalchemy/orm/session.py", line 1555, in _connection_for_bind
    return self._transaction._connection_for_bind(
           ^^^^^^^^^^^^^^^^^^^^^^^^^^^^^^^^^^^^^^^
  File "/home/airflow/.local/lib/python3.12/site-packages/sqlalchemy/orm/session.py", line 750, in _connection_for_bind
    conn = bind.connect()
           ^^^^^^^^^^^^^^
  File "/home/airflow/.local/lib/python3.12/site-packages/sqlalchemy/future/engine.py", line 412, in connect
    return super(Engine, self).connect()
           ^^^^^^^^^^^^^^^^^^^^^^^^^^^^^
  File "/home/airflow/.local/lib/python3.12/site-packages/sqlalchemy/engine/base.py", line 3325, in connect
    return self._connection_cls(self, close_with_result=close_with_result)
           ^^^^^^^^^^^^^^^^^^^^^^^^^^^^^^^^^^^^^^^^^^^^^^^^^^^^^^^^^^^^^^^
  File "/home/airflow/.local/lib/python3.12/site-packages/sqlalchemy/engine/base.py", line 96, in __init__
    else engine.raw_connection()
         ^^^^^^^^^^^^^^^^^^^^^^^
  File "/home/airflow/.local/lib/python3.12/site-packages/sqlalchemy/engine/base.py", line 3404, in raw_connection
    return self._wrap_pool_connect(self.pool.connect, _connection)
           ^^^^^^^^^^^^^^^^^^^^^^^^^^^^^^^^^^^^^^^^^^^^^^^^^^^^^^^
  File "/home/airflow/.local/lib/python3.12/site-packages/sqlalchemy/engine/base.py", line 3374, in _wrap_pool_connect
    Connection._handle_dbapi_exception_noconnection(
  File "/home/airflow/.local/lib/python3.12/site-packages/sqlalchemy/engine/base.py", line 2208, in _handle_dbapi_exception_noconnection
    util.raise_(
  File "/home/airflow/.local/lib/python3.12/site-packages/sqlalchemy/util/compat.py", line 211, in raise_
    raise exception
  File "/home/airflow/.local/lib/python3.12/site-packages/sqlalchemy/engine/base.py", line 3371, in _wrap_pool_connect
    return fn()
           ^^^^
  File "/home/airflow/.local/lib/python3.12/site-packages/sqlalchemy/pool/base.py", line 327, in connect
    return _ConnectionFairy._checkout(self)
           ^^^^^^^^^^^^^^^^^^^^^^^^^^^^^^^^
  File "/home/airflow/.local/lib/python3.12/site-packages/sqlalchemy/pool/base.py", line 894, in _checkout
    fairy = _ConnectionRecord.checkout(pool)
            ^^^^^^^^^^^^^^^^^^^^^^^^^^^^^^^^
  File "/home/airflow/.local/lib/python3.12/site-packages/sqlalchemy/pool/base.py", line 493, in checkout
    rec = pool._do_get()
          ^^^^^^^^^^^^^^
  File "/home/airflow/.local/lib/python3.12/site-packages/sqlalchemy/pool/impl.py", line 256, in _do_get
    return self._create_connection()
           ^^^^^^^^^^^^^^^^^^^^^^^^^
  File "/home/airflow/.local/lib/python3.12/site-packages/sqlalchemy/pool/base.py", line 273, in _create_connection
    return _ConnectionRecord(self)
           ^^^^^^^^^^^^^^^^^^^^^^^
  File "/home/airflow/.local/lib/python3.12/site-packages/sqlalchemy/pool/base.py", line 388, in __init__
    self.__connect()
  File "/home/airflow/.local/lib/python3.12/site-packages/sqlalchemy/pool/base.py", line 690, in __connect
    with util.safe_reraise():
         ^^^^^^^^^^^^^^^^^^^
  File "/home/airflow/.local/lib/python3.12/site-packages/sqlalchemy/util/langhelpers.py", line 70, in __exit__
    compat.raise_(
  File "/home/airflow/.local/lib/python3.12/site-packages/sqlalchemy/util/compat.py", line 211, in raise_
    raise exception
  File "/home/airflow/.local/lib/python3.12/site-packages/sqlalchemy/pool/base.py", line 686, in __connect
    self.dbapi_connection = connection = pool._invoke_creator(self)
                                         ^^^^^^^^^^^^^^^^^^^^^^^^^^
  File "/home/airflow/.local/lib/python3.12/site-packages/sqlalchemy/engine/create.py", line 574, in connect
    return dialect.connect(*cargs, **cparams)
           ^^^^^^^^^^^^^^^^^^^^^^^^^^^^^^^^^^
  File "/home/airflow/.local/lib/python3.12/site-packages/sqlalchemy/engine/default.py", line 598, in connect
    return self.dbapi.connect(*cargs, **cparams)
           ^^^^^^^^^^^^^^^^^^^^^^^^^^^^^^^^^^^^^
  File "/home/airflow/.local/lib/python3.12/site-packages/psycopg2/__init__.py", line 122, in connect
    conn = _connect(dsn, connection_factory=connection_factory, **kwasync)
           ^^^^^^^^^^^^^^^^^^^^^^^^^^^^^^^^^^^^^^^^^^^^^^^^^^^^^^^^^^^^^^^
sqlalchemy.exc.OperationalError: (psycopg2.OperationalError) could not translate host name "postgres" to address: Temporary failure in name resolution

(Background on this error at: https://sqlalche.me/e/14/e3q8)
[2024-10-19T00:05:29.418+0000] {job.py:254} ERROR - Job heartbeat failed with error. Scheduler is in unhealthy state
[2024-10-19T00:05:36.728+0000] {job.py:229} INFO - Heartbeat recovered after 22.28 seconds
[2024-10-19T00:06:25.280+0000] {process_utils.py:194} INFO - Running task via /home/***/.local/bin/python
[2024-10-19T00:06:25.527+0000] {process_utils.py:194} INFO - Sleeping
[2024-10-19T00:06:25.754+0000] {process_utils.py:194} INFO - Please wait...
[2024-10-19T00:06:26.237+0000] {process_utils.py:194} INFO - Please wait...
[2024-10-19T00:06:27.307+0000] {process_utils.py:194} INFO - Please wait...
[2024-10-19T00:06:28.309+0000] {process_utils.py:194} INFO - Please wait...
[2024-10-19T00:06:29.317+0000] {process_utils.py:194} INFO - Finished
[2024-10-19T00:07:00.620+0000] {python.py:240} INFO - Done. Returned value was: None
[2024-10-19T00:07:10.207+0000] {taskinstance.py:340} INFO - ::group::Post task execution logs
[2024-10-19T00:07:10.282+0000] {taskinstance.py:352} INFO - Marking task as SUCCESS. dag_id=example_python_operator, task_id=external_python, run_id=manual__2024-10-18T23:59:57.208019+00:00, execution_date=20241018T235957, start_date=20241019T000409, end_date=20241019T000710
[2024-10-19T00:07:11.056+0000] {logging_mixin.py:190} INFO - Task instance in success state
[2024-10-19T00:07:11.061+0000] {logging_mixin.py:190} INFO -  Previous state of the Task instance: running
[2024-10-19T00:07:11.063+0000] {logging_mixin.py:190} INFO - Dag name:example_python_operator queued_at:2024-10-18 23:59:57.327093+00:00
[2024-10-19T00:07:11.065+0000] {logging_mixin.py:190} INFO - Task hostname:bba1a6f01f4d operator:ExternalPythonOperator
