[2024-10-19T14:26:26.283+0000] {local_task_job_runner.py:123} INFO - ::group::Pre task execution logs
[2024-10-19T14:26:26.693+0000] {taskinstance.py:2612} INFO - Dependencies all met for dep_context=non-requeueable deps ti=<TaskInstance: tecnica_postgres.Crear_tabla manual__2024-10-19T14:25:25.130874+00:00 [queued]>
[2024-10-19T14:26:26.814+0000] {taskinstance.py:2612} INFO - Dependencies all met for dep_context=requeueable deps ti=<TaskInstance: tecnica_postgres.Crear_tabla manual__2024-10-19T14:25:25.130874+00:00 [queued]>
[2024-10-19T14:26:26.827+0000] {taskinstance.py:2865} INFO - Starting attempt 1 of 1
[2024-10-19T14:26:26.950+0000] {taskinstance.py:2888} INFO - Executing <Task(PostgresOperator): Crear_tabla> on 2024-10-19 14:25:25.130874+00:00
[2024-10-19T14:26:27.119+0000] {warnings.py:112} WARNING - /home/***/.local/lib/python3.12/site-packages/***/task/task_runner/standard_task_runner.py:70: DeprecationWarning: This process (pid=112) is multi-threaded, use of fork() may lead to deadlocks in the child.
  pid = os.fork()

[2024-10-19T14:26:27.154+0000] {standard_task_runner.py:72} INFO - Started process 125 to run task
[2024-10-19T14:26:27.356+0000] {standard_task_runner.py:104} INFO - Running: ['***', 'tasks', 'run', 'tecnica_postgres', 'Crear_tabla', 'manual__2024-10-19T14:25:25.130874+00:00', '--job-id', '144', '--raw', '--subdir', 'DAGS_FOLDER/tecnica_postgres.py', '--cfg-path', '/tmp/tmpzq3oxl_j']
[2024-10-19T14:26:27.394+0000] {standard_task_runner.py:105} INFO - Job 144: Subtask Crear_tabla
[2024-10-19T14:26:27.838+0000] {task_command.py:467} INFO - Running <TaskInstance: tecnica_postgres.Crear_tabla manual__2024-10-19T14:25:25.130874+00:00 [running]> on host 953088fb6bc9
[2024-10-19T14:26:28.523+0000] {taskinstance.py:3131} INFO - Exporting env vars: AIRFLOW_CTX_DAG_OWNER='***' AIRFLOW_CTX_DAG_ID='tecnica_postgres' AIRFLOW_CTX_TASK_ID='Crear_tabla' AIRFLOW_CTX_EXECUTION_DATE='2024-10-19T14:25:25.130874+00:00' AIRFLOW_CTX_TRY_NUMBER='1' AIRFLOW_CTX_DAG_RUN_ID='manual__2024-10-19T14:25:25.130874+00:00'
[2024-10-19T14:26:28.540+0000] {logging_mixin.py:190} INFO - Task instance is in running state
[2024-10-19T14:26:28.555+0000] {logging_mixin.py:190} INFO -  Previous state of the Task instance: queued
[2024-10-19T14:26:28.556+0000] {logging_mixin.py:190} INFO - Current task name:Crear_tabla state:running start_date:2024-10-19 14:26:26.704166+00:00
[2024-10-19T14:26:28.557+0000] {logging_mixin.py:190} INFO - Dag name:tecnica_postgres and current dag run status:running
[2024-10-19T14:26:28.558+0000] {taskinstance.py:731} INFO - ::endgroup::
[2024-10-19T14:26:28.560+0000] {sql.py:266} INFO - Executing: CREATE TABLE IF NOT EXISTS productos_mercadolibre (
            
            id varchar(500),
            site_id varchar(500),
            title varchar (500),
            price varchar(500),
            available_quantity varchar(200),
            thumbnail varchar(500),
            DATE varchar(100)
            
            )
[2024-10-19T14:26:28.639+0000] {base.py:84} INFO - Retrieving connection 'postgres_localhost'
[2024-10-19T14:26:28.694+0000] {base.py:84} INFO - Retrieving connection 'postgres_localhost'
[2024-10-19T14:26:38.895+0000] {taskinstance.py:3310} ERROR - Task failed with exception
Traceback (most recent call last):
  File "/home/airflow/.local/lib/python3.12/site-packages/airflow/models/taskinstance.py", line 767, in _execute_task
    result = _execute_callable(context=context, **execute_callable_kwargs)
             ^^^^^^^^^^^^^^^^^^^^^^^^^^^^^^^^^^^^^^^^^^^^^^^^^^^^^^^^^^^^^
  File "/home/airflow/.local/lib/python3.12/site-packages/airflow/models/taskinstance.py", line 733, in _execute_callable
    return ExecutionCallableRunner(
           ^^^^^^^^^^^^^^^^^^^^^^^^
  File "/home/airflow/.local/lib/python3.12/site-packages/airflow/utils/operator_helpers.py", line 252, in run
    return self.func(*args, **kwargs)
           ^^^^^^^^^^^^^^^^^^^^^^^^^^
  File "/home/airflow/.local/lib/python3.12/site-packages/airflow/models/baseoperator.py", line 406, in wrapper
    return func(self, *args, **kwargs)
           ^^^^^^^^^^^^^^^^^^^^^^^^^^^
  File "/home/airflow/.local/lib/python3.12/site-packages/airflow/providers/common/sql/operators/sql.py", line 272, in execute
    output = hook.run(
             ^^^^^^^^^
  File "/home/airflow/.local/lib/python3.12/site-packages/airflow/providers/common/sql/hooks/sql.py", line 452, in run
    with self._create_autocommit_connection(autocommit) as conn:
         ^^^^^^^^^^^^^^^^^^^^^^^^^^^^^^^^^^^^^^^^^^^^^^
  File "/usr/local/lib/python3.12/contextlib.py", line 137, in __enter__
    return next(self.gen)
           ^^^^^^^^^^^^^^
  File "/home/airflow/.local/lib/python3.12/site-packages/airflow/providers/common/sql/hooks/sql.py", line 574, in _create_autocommit_connection
    with closing(self.get_conn()) as conn:
                 ^^^^^^^^^^^^^^^
  File "/home/airflow/.local/lib/python3.12/site-packages/airflow/providers/postgres/hooks/postgres.py", line 176, in get_conn
    self.conn = psycopg2.connect(**conn_args)
                ^^^^^^^^^^^^^^^^^^^^^^^^^^^^^
  File "/home/airflow/.local/lib/python3.12/site-packages/psycopg2/__init__.py", line 122, in connect
    conn = _connect(dsn, connection_factory=connection_factory, **kwasync)
           ^^^^^^^^^^^^^^^^^^^^^^^^^^^^^^^^^^^^^^^^^^^^^^^^^^^^^^^^^^^^^^^
psycopg2.OperationalError: could not translate host name "host.docker.internal" to address: Temporary failure in name resolution

[2024-10-19T14:26:51.711+0000] {logging_mixin.py:190} INFO - Task instance in failure state
[2024-10-19T14:26:51.733+0000] {logging_mixin.py:190} INFO - Task start:2024-10-19 14:26:26.704166+00:00 end:2024-10-19 14:26:51.645620+00:00 duration:24.941454
[2024-10-19T14:26:51.776+0000] {logging_mixin.py:190} INFO - Task:<Task(PostgresOperator): Crear_tabla> dag:<DAG: tecnica_postgres> dagrun:<DagRun tecnica_postgres @ 2024-10-19 14:25:25.130874+00:00: manual__2024-10-19T14:25:25.130874+00:00, state:running, queued_at: 2024-10-19 14:25:25.545293+00:00. externally triggered: True>
[2024-10-19T14:26:51.784+0000] {logging_mixin.py:190} INFO - Failure caused by could not translate host name "host.docker.internal" to address: Temporary failure in name resolution
[2024-10-19T14:26:51.820+0000] {taskinstance.py:1225} INFO - Marking task as FAILED. dag_id=tecnica_postgres, task_id=Crear_tabla, run_id=manual__2024-10-19T14:25:25.130874+00:00, execution_date=20241019T142525, start_date=20241019T142626, end_date=20241019T142651
[2024-10-19T14:26:52.085+0000] {job.py:229} INFO - Heartbeat recovered after 26.37 seconds
[2024-10-19T14:26:52.489+0000] {taskinstance.py:340} INFO - ::group::Post task execution logs
[2024-10-19T14:26:52.522+0000] {standard_task_runner.py:124} ERROR - Failed to execute job 144 for task Crear_tabla (could not translate host name "host.docker.internal" to address: Temporary failure in name resolution
; 125)
Traceback (most recent call last):
  File "/home/airflow/.local/lib/python3.12/site-packages/airflow/task/task_runner/standard_task_runner.py", line 117, in _start_by_fork
    ret = args.func(args, dag=self.dag)
          ^^^^^^^^^^^^^^^^^^^^^^^^^^^^^
  File "/home/airflow/.local/lib/python3.12/site-packages/airflow/cli/cli_config.py", line 49, in command
    return func(*args, **kwargs)
           ^^^^^^^^^^^^^^^^^^^^^
  File "/home/airflow/.local/lib/python3.12/site-packages/airflow/utils/cli.py", line 115, in wrapper
    return f(*args, **kwargs)
           ^^^^^^^^^^^^^^^^^^
  File "/home/airflow/.local/lib/python3.12/site-packages/airflow/cli/commands/task_command.py", line 483, in task_run
    task_return_code = _run_task_by_selected_method(args, _dag, ti)
                       ^^^^^^^^^^^^^^^^^^^^^^^^^^^^^^^^^^^^^^^^^^^^
  File "/home/airflow/.local/lib/python3.12/site-packages/airflow/cli/commands/task_command.py", line 256, in _run_task_by_selected_method
    return _run_raw_task(args, ti)
           ^^^^^^^^^^^^^^^^^^^^^^^
  File "/home/airflow/.local/lib/python3.12/site-packages/airflow/cli/commands/task_command.py", line 341, in _run_raw_task
    return ti._run_raw_task(
           ^^^^^^^^^^^^^^^^^
  File "/home/airflow/.local/lib/python3.12/site-packages/airflow/utils/session.py", line 97, in wrapper
    return func(*args, session=session, **kwargs)
           ^^^^^^^^^^^^^^^^^^^^^^^^^^^^^^^^^^^^^^
  File "/home/airflow/.local/lib/python3.12/site-packages/airflow/models/taskinstance.py", line 3004, in _run_raw_task
    return _run_raw_task(
           ^^^^^^^^^^^^^^
  File "/home/airflow/.local/lib/python3.12/site-packages/airflow/models/taskinstance.py", line 273, in _run_raw_task
    TaskInstance._execute_task_with_callbacks(
  File "/home/airflow/.local/lib/python3.12/site-packages/airflow/models/taskinstance.py", line 3158, in _execute_task_with_callbacks
    result = self._execute_task(context, task_orig)
             ^^^^^^^^^^^^^^^^^^^^^^^^^^^^^^^^^^^^^^
  File "/home/airflow/.local/lib/python3.12/site-packages/airflow/models/taskinstance.py", line 3182, in _execute_task
    return _execute_task(self, context, task_orig)
           ^^^^^^^^^^^^^^^^^^^^^^^^^^^^^^^^^^^^^^^
  File "/home/airflow/.local/lib/python3.12/site-packages/airflow/models/taskinstance.py", line 767, in _execute_task
    result = _execute_callable(context=context, **execute_callable_kwargs)
             ^^^^^^^^^^^^^^^^^^^^^^^^^^^^^^^^^^^^^^^^^^^^^^^^^^^^^^^^^^^^^
  File "/home/airflow/.local/lib/python3.12/site-packages/airflow/models/taskinstance.py", line 733, in _execute_callable
    return ExecutionCallableRunner(
           ^^^^^^^^^^^^^^^^^^^^^^^^
  File "/home/airflow/.local/lib/python3.12/site-packages/airflow/utils/operator_helpers.py", line 252, in run
    return self.func(*args, **kwargs)
           ^^^^^^^^^^^^^^^^^^^^^^^^^^
  File "/home/airflow/.local/lib/python3.12/site-packages/airflow/models/baseoperator.py", line 406, in wrapper
    return func(self, *args, **kwargs)
           ^^^^^^^^^^^^^^^^^^^^^^^^^^^
  File "/home/airflow/.local/lib/python3.12/site-packages/airflow/providers/common/sql/operators/sql.py", line 272, in execute
    output = hook.run(
             ^^^^^^^^^
  File "/home/airflow/.local/lib/python3.12/site-packages/airflow/providers/common/sql/hooks/sql.py", line 452, in run
    with self._create_autocommit_connection(autocommit) as conn:
         ^^^^^^^^^^^^^^^^^^^^^^^^^^^^^^^^^^^^^^^^^^^^^^
  File "/usr/local/lib/python3.12/contextlib.py", line 137, in __enter__
    return next(self.gen)
           ^^^^^^^^^^^^^^
  File "/home/airflow/.local/lib/python3.12/site-packages/airflow/providers/common/sql/hooks/sql.py", line 574, in _create_autocommit_connection
    with closing(self.get_conn()) as conn:
                 ^^^^^^^^^^^^^^^
  File "/home/airflow/.local/lib/python3.12/site-packages/airflow/providers/postgres/hooks/postgres.py", line 176, in get_conn
    self.conn = psycopg2.connect(**conn_args)
                ^^^^^^^^^^^^^^^^^^^^^^^^^^^^^
  File "/home/airflow/.local/lib/python3.12/site-packages/psycopg2/__init__.py", line 122, in connect
    conn = _connect(dsn, connection_factory=connection_factory, **kwasync)
           ^^^^^^^^^^^^^^^^^^^^^^^^^^^^^^^^^^^^^^^^^^^^^^^^^^^^^^^^^^^^^^^
psycopg2.OperationalError: could not translate host name "host.docker.internal" to address: Temporary failure in name resolution

[2024-10-19T14:26:53.330+0000] {local_task_job_runner.py:266} INFO - Task exited with return code 1
[2024-10-19T14:26:53.745+0000] {local_task_job_runner.py:245} INFO - ::endgroup::
[2024-10-19T14:26:56.132+0000] {standard_task_runner.py:217} INFO - Process not found (most likely exited), stop collecting metrics
